Workbook

Sheet Start Here
A1: Meal Prep System
A2: Two lunches + two dinners a week. Options mix new AI-suggested recipes with favourites from your own recipe bank.
A4: THE WEEKLY LOOP
A5: 1. Sunday — the pitch. Two or three options per slot (Lunch 1, Lunch 2, Dinner 1, Dinner 2): new AI picks plus recipe-bank favourites. New recipes go on Recipes; each option gets a row on Weekly Log with picked = No.
A6: 2. You both reply with a pick for each slot. Flip those rows to picked = Yes.
A7: 3. Make sure each picked recipe's ingredients are on the Ingredients tab. The Grocery List tab then builds itself: duplicates added up, sorted by aisle, pantry staples last.
A8: 4. Following Sunday — the debrief. Fill rating_lily / rating_andrei (1–5) and verdict (Again / Tweak / Never) for last week's picks. For Tweak, write what should change in the tweak column; it then shows as latest_tweak on Recipes so the next pitch includes it.
A10: WHAT EACH TAB IS
A11: Recipes — every recipe you've ever been offered. Grey columns count how often it's been offered, picked, its average rating and when you last made it.
A12: Weekly Log — every option offered, every week. Logging the ones you passed on too is what makes pick_rate meaningful.
A13: Ingredients — one row per ingredient per recipe. Entered once per recipe, reused every time you make it again.
A14: Ingredient Catalog — each ingredient once, with one spelling, one unit, an aisle and whether it's a pantry staple.
... A25: Formulas are pre-filled for 500 recipes, 3,000 ingredient rows, 500 catalog items and 1,000 log rows — years of weekly prep, far past a two-month trial.

Sheet Recipes
A1: Recipes — one row per recipe, ever
A2: Yellow headers: you fill in. Grey headers: calculated from the Weekly Log, don't type in them. Grey italic EX rows are examples; delete them before week 1.
A3: recipe_id | B3: name | C3: source | D3: url | E3: meal_type | F3: cuisine | G3: servings | H3: added_on | I3: status | J3: times_offered | K3: times_picked | L3: pick_rate | M3: avg_rating | N3: last_made | O3: weeks_since_made | P3: notes | Q3: latest_tweak
A4: EX01 | B4: Chicken burrito bowls | C4: AI | E4: Lunch | F4: Mexican | G4: 4 | H4: 46312 | I4: Active | J4: =IF(A4="","",COUNTIF('Weekly Log'!$C:$C,A4)) -> 1 | K4: =IF(A4="","",COUNTIFS('Weekly Log'!$C:$C,A4,'Weekly Log'!$E:$E,"Yes")) -> 0 | L4: =IF(A4="","",IF(J4=0,"",K4/J4)) -> 0 | M4: =IF(A4="","",IFERROR((SUMIFS('Weekly Log'!$F:$F,'Weekly Log'!$C:$C,A4)+SUMIFS('Weekly Log'!$G:$G,'Weekly Log'!$C:$C,A4))/(COUNTIFS('Weekly Log'!$C:$C,A4,'Weekly Log'!$F:$F,"<>")+COUNTIFS('Weekly Log'!$C:$C,A4,'Weekly Log'!$G:$G,"<>")),"")) | N4: =IF(A4="","",IF(K4=0,"",_xlfn.MAXIFS('Weekly Log'!$A:$A,'Weekly Log'!$C:$C,A4,'Weekly Log'!$E:$E,"Yes"))) | O4: =IF(N4="","",MAX(0,INT((TODAY()-N4)/7))) | Q4: =IF(A4="","",IFERROR(LOOKUP(2,1/(('Weekly Log'!$C$4:$C$1003=A4)*('Weekly Log'!$I$4:$I$1003<>"")),'Weekly Log'!$I$4:$I$1003),""))
A5: EX02 | B5: Cold sesame noodles with cucumber | C5: AI | E5: Lunch | F5: Chinese | G5: 4 | H5: 46312 | I5: Active | J5: =IF(A5="","",COUNTIF('Weekly Log'!$C:$C,A5)) -> 1 | K5: =IF(A5="","",COUNTIFS('Weekly Log'!$C:$C,A5,'Weekly Log'!$E:$E,"Yes")) -> 1 | L5: =IF(A5="","",IF(J5=0,"",K5/J5)) -> 1 | M5: =IF(A5="","",IFERROR((SUMIFS('Weekly Log'!$F:$F,'Weekly Log'!$C:$C,A5)+SUMIFS('Weekly Log'!$G:$G,'Weekly Log'!$C:$C,A5))/(COUNTIFS('Weekly Log'!$C:$C,A5,'Weekly Log'!$F:$F,"<>")+COUNTIFS('Weekly Log'!$C:$C,A5,'Weekly Log'!$G:$G,"<>")),"")) | N5: =IF(A5="","",IF(K5=0,"",_xlfn.MAXIFS('Weekly Log'!$A:$A,'Weekly Log'!$C:$C,A5,'Weekly Log'!$E:$E,"Yes"))) -> 46313 | O5: =IF(N5="","",MAX(0,INT((TODAY()-N5)/7))) -> 0 | Q5: =IF(A5="","",IFERROR(LOOKUP(2,1/(('Weekly Log'!$C$4:$C$1003=A5)*('Weekly Log'!$I$4:$I$1003<>"")),'Weekly Log'!$I$4:$I$1003),""))
A6: EX03 | B6: Ciorbă de perișoare (meatball soup) | C6: Own | E6: Lunch | F6: Romanian | G6: 6 | H6: 46305 | I6: Active | J6: =IF(A6="","",COUNTIF('Weekly Log'!$C:$C,A6)) -> 2 | K6: =IF(A6="","",COUNTIFS('Weekly Log'!$C:$C,A6,'Weekly Log'!$E:$E,"Yes")) -> 2 | L6: =IF(A6="","",IF(J6=0,"",K6/J6)) -> 1 | M6: =IF(A6="","",IFERROR((SUMIFS('Weekly Log'!$F:$F,'Weekly Log'!$C:$C,A6)+SUMIFS('Weekly Log'!$G:$G,'Weekly Log'!$C:$C,A6))/(COUNTIFS('Weekly Log'!$C:$C,A6,'Weekly Log'!$F:$F,"<>")+COUNTIFS('Weekly Log'!$C:$C,A6,'Weekly Log'!$G:$G,"<>")),"")) -> 4.5 | N6: =IF(A6="","",IF(K6=0,"",_xlfn.MAXIFS('Weekly Log'!$A:$A,'Weekly Log'!$C:$C,A6,'Weekly Log'!$E:$E,"Yes"))) -> 46313 | O6: =IF(N6="","",MAX(0,INT((TODAY()-N6)/7))) -> 0 | Q6: =IF(A6="","",IFERROR(LOOKUP(2,1/(('Weekly Log'!$C$4:$C$1003=A6)*('Weekly Log'!$I$4:$I$1003<>"")),'Weekly Log'!$I$4:$I$1003),"")) -> Extra lovage, more borș
A7: EX04 | B7: Greek chicken orzo | C7: AI | E7: Lunch | F7: Mediterranean | G7: 4 | H7: 46312 | I7: Active | J7: =IF(A7="","",COUNTIF('Weekly Log'!$C:$C,A7)) -> 1 | K7: =IF(A7="","",COUNTIFS('Weekly Log'!$C:$C,A7,'Weekly Log'!$E:$E,"Yes")) -> 0 | L7: =IF(A7="","",IF(J7=0,"",K7/J7)) -> 0 | M7: =IF(A7="","",IFERROR((SUMIFS('Weekly Log'!$F:$F,'Weekly Log'!$C:$C,A7)+SUMIFS('Weekly Log'!$G:$G,'Weekly Log'!$C:$C,A7))/(COUNTIFS('Weekly Log'!$C:$C,A7,'Weekly Log'!$F:$F,"<>")+COUNTIFS('Weekly Log'!$C:$C,A7,'Weekly Log'!$G:$G,"<>")),"")) | N7: =IF(A7="","",IF(K7=0,"",_xlfn.MAXIFS('Weekly Log'!$A:$A,'Weekly Log'!$C:$C,A7,'Weekly Log'!$E:$E,"Yes"))) | O7: =IF(N7="","",MAX(0,INT((TODAY()-N7)/7))) | Q7: =IF(A7="","",IFERROR(LOOKUP(2,1/(('Weekly Log'!$C$4:$C$1003=A7)*('Weekly Log'!$I$4:$I$1003<>"")),'Weekly Log'!$I$4:$I$1003),""))
A8: EX05 | B8: Sheet-pan sausage, peppers & potatoes | C8: AI | E8: Dinner | F8: American | G8: 4 | H8: 46312 | I8: Active | J8: =IF(A8="","",COUNTIF('Weekly Log'!$C:$C,A8)) -> 1 | K8: =IF(A8="","",COUNTIFS('Weekly Log'!$C:$C,A8,'Weekly Log'!$E:$E,"Yes")) -> 1 | L8: =IF(A8="","",IF(J8=0,"",K8/J8)) -> 1 | M8: =IF(A8="","",IFERROR((SUMIFS('Weekly Log'!$F:$F,'Weekly Log'!$C:$C,A8)+SUMIFS('Weekly Log'!$G:$G,'Weekly Log'!$C:$C,A8))/(COUNTIFS('Weekly Log'!$C:$C,A8,'Weekly Log'!$F:$F,"<>")+COUNTIFS('Weekly Log'!$C:$C,A8,'Weekly Log'!$G:$G,"<>")),"")) | N8: =IF(A8="","",IF(K8=0,"",_xlfn.MAXIFS('Weekly Log'!$A:$A,'Weekly Log'!$C:$C,A8,'Weekly Log'!$E:$E,"Yes"))) -> 46313 | O8: =IF(N8="","",MAX(0,INT((TODAY()-N8)/7))) -> 0 | Q8: =IF(A8="","",IFERROR(LOOKUP(2,1/(('Weekly Log'!$C$4:$C$1003=A8)*('Weekly Log'!$I$4:$I$1003<>"")),'Weekly Log'!$I$4:$I$1003),""))
A9: EX06 | B9: Red-braised pork belly (hong shao rou) | C9: AI | E9: Dinner | F9: Chinese | G9: 4 | H9: 46312 | I9: Active | J9: =IF(A9="","",COUNTIF('Weekly Log'!$C:$C,A9)) -> 1 | K9: =IF(A9="","",COUNTIFS('Weekly Log'!$C:$C,A9,'Weekly Log'!$E:$E,"Yes")) -> 0 | L9: =IF(A9="","",IF(J9=0,"",K9/J9)) -> 0 | M9: =IF(A9="","",IFERROR((SUMIFS('Weekly Log'!$F:$F,'Weekly Log'!$C:$C,A9)+SUMIFS('Weekly Log'!$G:$G,'Weekly Log'!$C:$C,A9))/(COUNTIFS('Weekly Log'!$C:$C,A9,'Weekly Log'!$F:$F,"<>")+COUNTIFS('Weekly Log'!$C:$C,A9,'Weekly Log'!$G:$G,"<>")),"")) | N9: =IF(A9="","",IF(K9=0,"",_xlfn.MAXIFS('Weekly Log'!$A:$A,'Weekly Log'!$C:$C,A9,'Weekly Log'!$E:$E,"Yes"))) | O9: =IF(N9="","",MAX(0,INT((TODAY()-N9)/7))) | Q9: =IF(A9="","",IFERROR(LOOKUP(2,1/(('Weekly Log'!$C$4:$C$1003=A9)*('Weekly Log'!$I$4:$I$1003<>"")),'Weekly Log'!$I$4:$I$1003),""))
A10: EX07 | B10: Tomato egg stir-fry | C10: Own | E10: Dinner | F10: Chinese | G10: 2 | H10: 46305 | I10: Active | J10: =IF(A10="","",COUNTIF('Weekly Log'!$C:$C,A10)) -> 2 | K10: =IF(A10="","",COUNTIFS('Weekly Log'!$C:$C,A10,'Weekly Log'!$E:$E,"Yes")) -> 1 | L10: =IF(A10="","",IF(J10=0,"",K10/J10)) -> 0.5 | M10: =IF(A10="","",IFERROR((SUMIFS('Weekly Log'!$F:$F,'Weekly Log'!$C:$C,A10)+SUMIFS('Weekly Log'!$G:$G,'Weekly Log'!$C:$C,A10))/(COUNTIFS('Weekly Log'!$C:$C,A10,'Weekly Log'!$F:$F,"<>")+COUNTIFS('Weekly Log'!$C:$C,A10,'Weekly Log'!$G:$G,"<>")),"")) -> 4.5 | N10: =IF(A10="","",IF(K10=0,"",_xlfn.MAXIFS('Weekly Log'!$A:$A,'Weekly Log'!$C:$C,A10,'Weekly Log'!$E:$E,"Yes"))) -> 46306 | O10: =IF(N10="","",MAX(0,INT((TODAY()-N10)/7))) -> 0 | Q10: =IF(A10="","",IFERROR(LOOKUP(2,1/(('Weekly Log'!$C$4:$C$1003=A10)*('Weekly Log'!$I$4:$I$1003<>"")),'Weekly Log'!$I$4:$I$1003),""))
A11: EX08 | B11: Chicken papricaș with mămăligă | C11: AI | E11: Dinner | F11: Romanian | G11: 4 | H11: 46312 | I11: Active | J11: =IF(A11="","",COUNTIF('Weekly Log'!$C:$C,A11)) -> 1 | K11: =IF(A11="","",COUNTIFS('Weekly Log'!$C:$C,A11,'Weekly Log'!$E:$E,"Yes")) -> 1 | L11: =IF(A11="","",IF(J11=0,"",K11/J11)) -> 1 | M11: =IF(A11="","",IFERROR((SUMIFS('Weekly Log'!$F:$F,'Weekly Log'!$C:$C,A11)+SUMIFS('Weekly Log'!$G:$G,'Weekly Log'!$C:$C,A11))/(COUNTIFS('Weekly Log'!$C:$C,A11,'Weekly Log'!$F:$F,"<>")+COUNTIFS('Weekly Log'!$C:$C,A11,'Weekly Log'!$G:$G,"<>")),"")) | N11: =IF(A11="","",IF(K11=0,"",_xlfn.MAXIFS('Weekly Log'!$A:$A,'Weekly Log'!$C:$C,A11,'Weekly Log'!$E:$E,"Yes"))) -> 46313 | O11: =IF(N11="","",MAX(0,INT((TODAY()-N11)/7))) -> 0 | Q11: =IF(A11="","",IFERROR(LOOKUP(2,1/(('Weekly Log'!$C$4:$C$1003=A11)*('Weekly Log'!$I$4:$I$1003<>"")),'Weekly Log'!$I$4:$I$1003),""))
J12: =IF(A12="","",COUNTIF('Weekly Log'!$C:$C,A12)) | K12: =IF(A12="","",COUNTIFS('Weekly Log'!$C:$C,A12,'Weekly Log'!$E:$E,"Yes")) | L12: =IF(A12="","",IF(J12=0,"",K12/J12)) | M12: =IF(A12="","",IFERROR((SUMIFS('Weekly Log'!$F:$F,'Weekly Log'!$C:$C,A12)+SUMIFS('Weekly Log'!$G:$G,'Weekly Log'!$C:$C,A12))/(COUNTIFS('Weekly Log'!$C:$C,A12,'Weekly Log'!$F:$F,"<>")+COUNTIFS('Weekly Log'!$C:$C,A12,'Weekly Log'!$G:$G,"<>")),"")) | N12: =IF(A12="","",IF(K12=0,"",_xlfn.MAXIFS('Weekly Log'!$A:$A,'Weekly Log'!$C:$C,A12,'Weekly Log'!$E:$E,"Yes"))) | O12: =IF(N12="","",MAX(0,INT((TODAY()-N12)/7))) | Q12: =IF(A12="","",IFERROR(LOOKUP(2,1/(('Weekly Log'!$C$4:$C$1003=A12)*('Weekly Log'!$I$4:$I$1003<>"")),'Weekly Log'!$I$4:$I$1003),""))
J13: =IF(A13="","",COUNTIF('Weekly Log'!$C:$C,A13)) | K13: =IF(A13="","",COUNTIFS('Weekly Log'!$C:$C,A13,'Weekly Log'!$E:$E,"Yes")) | L13: =IF(A13="","",IF(J13=0,"",K13/J13)) | M13: =IF(A13="","",IFERROR((SUMIFS('Weekly Log'!$F:$F,'Weekly Log'!$C:$C,A13)+SUMIFS('Weekly Log'!$G:$G,'Weekly Log'!$C:$C,A13))/(COUNTIFS('Weekly Log'!$C:$C,A13,'Weekly Log'!$F:$F,"<>")+COUNTIFS('Weekly Log'!$C:$C,A13,'Weekly Log'!$G:$G,"<>")),"")) | N13: =IF(A13="","",IF(K13=0,"",_xlfn.MAXIFS('Weekly Log'!$A:$A,'Weekly Log'!$C:$C,A13,'Weekly Log'!$E:$E,"Yes"))) | O13: =IF(N13="","",MAX(0,INT((TODAY()-N13)/7))) | Q13: =IF(A13="","",IFERROR(LOOKUP(2,1/(('Weekly Log'!$C$4:$C$1003=A13)*('Weekly Log'!$I$4:$I$1003<>"")),'Weekly Log'!$I$4:$I$1003),""))
J14: =IF(A14="","",COUNTIF('Weekly Log'!$C:$C,A14)) | K14: =IF(A14="","",COUNTIFS('Weekly Log'!$C:$C,A14,'Weekly Log'!$E:$E,"Yes")) | L14: =IF(A14="","",IF(J14=0,"",K14/J14)) | M14: =IF(A14="","",IFERROR((SUMIFS('Weekly Log'!$F:$F,'Weekly Log'!$C:$C,A14)+SUMIFS('Weekly Log'!$G:$G,'Weekly Log'!$C:$C,A14))/(COUNTIFS('Weekly Log'!$C:$C,A14,'Weekly Log'!$F:$F,"<>")+COUNTIFS('Weekly Log'!$C:$C,A14,'Weekly Log'!$G:$G,"<>")),"")) | N14: =IF(A14="","",IF(K14=0,"",_xlfn.MAXIFS('Weekly Log'!$A:$A,'Weekly Log'!$C:$C,A14,'Weekly Log'!$E:$E,"Yes"))) | O14: =IF(N14="","",MAX(0,INT((TODAY()-N14)/7))) | Q14: =IF(A14="","",IFERROR(LOOKUP(2,1/(('Weekly Log'!$C$4:$C$1003=A14)*('Weekly Log'!$I$4:$I$1003<>"")),'Weekly Log'!$I$4:$I$1003),""))
J15: =IF(A15="","",COUNTIF('Weekly Log'!$C:$C,A15)) | K15: =IF(A15="","",COUNTIFS('Weekly Log'!$C:$C,A15,'Weekly Log'!$E:$E,"Yes")) | L15: =IF(A15="","",IF(J15=0,"",K15/J15)) | M15: =IF(A15="","",IFERROR((SUMIFS('Weekly Log'!$F:$F,'Weekly Log'!$C:$C,A15)+SUMIFS('Weekly Log'!$G:$G,'Weekly Log'!$C:$C,A15))/(COUNTIFS('Weekly Log'!$C:$C,A15,'Weekly Log'!$F:$F,"<>")+COUNTIFS('Weekly Log'!$C:$C,A15,'Weekly Log'!$G:$G,"<>")),"")) | N15: =IF(A15="","",IF(K15=0,"",_xlfn.MAXIFS('Weekly Log'!$A:$A,'Weekly Log'!$C:$C,A15,'Weekly Log'!$E:$E,"Yes"))) | O15: =IF(N15="","",MAX(0,INT((TODAY()-N15)/7))) | Q15: =IF(A15="","",IFERROR(LOOKUP(2,1/(('Weekly Log'!$C$4:$C$1003=A15)*('Weekly Log'!$I$4:$I$1003<>"")),'Weekly Log'!$I$4:$I$1003),""))
J16: =IF(A16="","",COUNTIF('Weekly Log'!$C:$C,A16)) | K16: =IF(A16="","",COUNTIFS('Weekly Log'!$C:$C,A16,'Weekly Log'!$E:$E,"Yes")) | L16: =IF(A16="","",IF(J16=0,"",K16/J16)) | M16: =IF(A16="","",IFERROR((SUMIFS('Weekly Log'!$F:$F,'Weekly Log'!$C:$C,A16)+SUMIFS('Weekly Log'!$G:$G,'Weekly Log'!$C:$C,A16))/(COUNTIFS('Weekly Log'!$C:$C,A16,'Weekly Log'!$F:$F,"<>")+COUNTIFS('Weekly Log'!$C:$C,A16,'Weekly Log'!$G:$G,"<>")),"")) | N16: =IF(A16="","",IF(K16=0,"",_xlfn.MAXIFS('Weekly Log'!$A:$A,'Weekly Log'!$C:$C,A16,'Weekly Log'!$E:$E,"Yes"))) | O16: =IF(N16="","",MAX(0,INT((TODAY()-N16)/7))) | Q16: =IF(A16="","",IFERROR(LOOKUP(2,1/(('Weekly Log'!$C$4:$C$1003=A16)*('Weekly Log'!$I$4:$I$1003<>"")),'Weekly Log'!$I$4:$I$1003),""))
J17: =IF(A17="","",COUNTIF('Weekly Log'!$C:$C,A17)) | K17: =IF(A17="","",COUNTIFS('Weekly Log'!$C:$C,A17,'Weekly Log'!$E:$E,"Yes")) | L17: =IF(A17="","",IF(J17=0,"",K17/J17)) | M17: =IF(A17="","",IFERROR((SUMIFS('Weekly Log'!$F:$F,'Weekly Log'!$C:$C,A17)+SUMIFS('Weekly Log'!$G:$G,'Weekly Log'!$C:$C,A17))/(COUNTIFS('Weekly Log'!$C:$C,A17,'Weekly Log'!$F:$F,"<>")+COUNTIFS('Weekly Log'!$C:$C,A17,'Weekly Log'!$G:$G,"<>")),"")) | N17: =IF(A17="","",IF(K17=0,"",_xlfn.MAXIFS('Weekly Log'!$A:$A,'Weekly Log'!$C:$C,A17,'Weekly Log'!$E:$E,"Yes"))) | O17: =IF(N17="","",MAX(0,INT((TODAY()-N17)/7))) | Q17: =IF(A17="","",IFERROR(LOOKUP(2,1/(('Weekly Log'!$C$4:$C$1003=A17)*('Weekly Log'!$I$4:$I$1003<>"")),'Weekly Log'!$I$4:$I$1003),""))
J18: =IF(A18="","",COUNTIF('Weekly Log'!$C:$C,A18)) | K18: =IF(A18="","",COUNTIFS('Weekly Log'!$C:$C,A18,'Weekly Log'!$E:$E,"Yes")) | L18: =IF(A18="","",IF(J18=0,"",K18/J18)) | M18: =IF(A18="","",IFERROR((SUMIFS('Weekly Log'!$F:$F,'Weekly Log'!$C:$C,A18)+SUMIFS('Weekly Log'!$G:$G,'Weekly Log'!$C:$C,A18))/(COUNTIFS('Weekly Log'!$C:$C,A18,'Weekly Log'!$F:$F,"<>")+COUNTIFS('Weekly Log'!$C:$C,A18,'Weekly Log'!$G:$G,"<>")),"")) | N18: =IF(A18="","",IF(K18=0,"",_xlfn.MAXIFS('Weekly Log'!$A:$A,'Weekly Log'!$C:$C,A18,'Weekly Log'!$E:$E,"Yes"))) | O18: =IF(N18="","",MAX(0,INT((TODAY()-N18)/7))) | Q18: =IF(A18="","",IFERROR(LOOKUP(2,1/(('Weekly Log'!$C$4:$C$1003=A18)*('Weekly Log'!$I$4:$I$1003<>"")),'Weekly Log'!$I$4:$I$1003),""))
J19: =IF(A19="","",COUNTIF('Weekly Log'!$C:$C,A19)) | K19: =IF(A19="","",COUNTIFS('Weekly Log'!$C:$C,A19,'Weekly Log'!$E:$E,"Yes")) | L19: =IF(A19="","",IF(J19=0,"",K19/J19)) | M19: =IF(A19="","",IFERROR((SUMIFS('Weekly Log'!$F:$F,'Weekly Log'!$C:$C,A19)+SUMIFS('Weekly Log'!$G:$G,'Weekly Log'!$C:$C,A19))/(COUNTIFS('Weekly Log'!$C:$C,A19,'Weekly Log'!$F:$F,"<>")+COUNTIFS('Weekly Log'!$C:$C,A19,'Weekly Log'!$G:$G,"<>")),"")) | N19: =IF(A19="","",IF(K19=0,"",_xlfn.MAXIFS('Weekly Log'!$A:$A,'Weekly Log'!$C:$C,A19,'Weekly Log'!$E:$E,"Yes"))) | O19: =IF(N19="","",MAX(0,INT((TODAY()-N19)/7))) | Q19: =IF(A19="","",IFERROR(LOOKUP(2,1/(('Weekly Log'!$C$4:$C$1003=A19)*('Weekly Log'!$I$4:$I$1003<>"")),'Weekly Log'!$I$4:$I$1003),""))
J20: =IF(A20="","",COUNTIF('Weekly Log'!$C:$C,A20)) | K20: =IF(A20="","",COUNTIFS('Weekly Log'!$C:$C,A20,'Weekly Log'!$E:$E,"Yes")) | L20: =IF(A20="","",IF(J20=0,"",K20/J20)) | M20: =IF(A20="","",IFERROR((SUMIFS('Weekly Log'!$F:$F,'Weekly Log'!$C:$C,A20)+SUMIFS('Weekly Log'!$G:$G,'Weekly Log'!$C:$C,A20))/(COUNTIFS('Weekly Log'!$C:$C,A20,'Weekly Log'!$F:$F,"<>")+COUNTIFS('Weekly Log'!$C:$C,A20,'Weekly Log'!$G:$G,"<>")),"")) | N20: =IF(A20="","",IF(K20=0,"",_xlfn.MAXIFS('Weekly Log'!$A:$A,'Weekly Log'!$C:$C,A20,'Weekly Log'!$E:$E,"Yes"))) | O20: =IF(N20="","",MAX(0,INT((TODAY()-N20)/7))) | Q20: =IF(A20="","",IFERROR(LOOKUP(2,1/(('Weekly Log'!$C$4:$C$1003=A20)*('Weekly Log'!$I$4:$I$1003<>"")),'Weekly Log'!$I$4:$I$1003),""))
J21: =IF(A21="","",COUNTIF('Weekly Log'!$C:$C,A21)) | K21: =IF(A21="","",COUNTIFS('Weekly Log'!$C:$C,A21,'Weekly Log'!$E:$E,"Yes")) | L21: =IF(A21="","",IF(J21=0,"",K21/J21)) | M21: =IF(A21="","",IFERROR((SUMIFS('Weekly Log'!$F:$F,'Weekly Log'!$C:$C,A21)+SUMIFS('Weekly Log'!$G:$G,'Weekly Log'!$C:$C,A21))/(COUNTIFS('Weekly Log'!$C:$C,A21,'Weekly Log'!$F:$F,"<>")+COUNTIFS('Weekly Log'!$C:$C,A21,'Weekly Log'!$G:$G,"<>")),"")) | N21: =IF(A21="","",IF(K21=0,"",_xlfn.MAXIFS('Weekly Log'!$A:$A,'Weekly Log'!$C:$C,A21,'Weekly Log'!$E:$E,"Yes"))) | O21: =IF(N21="","",MAX(0,INT((TODAY()-N21)/7))) | Q21: =IF(A21="","",IFERROR(LOOKUP(2,1/(('Weekly Log'!$C$4:$C$1003=A21)*('Weekly Log'!$I$4:$I$1003<>"")),'Weekly Log'!$I$4:$I$1003),""))
J22: =IF(A22="","",COUNTIF('Weekly Log'!$C:$C,A22)) | K22: =IF(A22="","",COUNTIFS('Weekly Log'!$C:$C,A22,'Weekly Log'!$E:$E,"Yes")) | L22: =IF(A22="","",IF(J22=0,"",K22/J22)) | M22: =IF(A22="","",IFERROR((SUMIFS('Weekly Log'!$F:$F,'Weekly Log'!$C:$C,A22)+SUMIFS('Weekly Log'!$G:$G,'Weekly Log'!$C:$C,A22))/(COUNTIFS('Weekly Log'!$C:$C,A22,'Weekly Log'!$F:$F,"<>")+COUNTIFS('Weekly Log'!$C:$C,A22,'Weekly Log'!$G:$G,"<>")),"")) | N22: =IF(A22="","",IF(K22=0,"",_xlfn.MAXIFS('Weekly Log'!$A:$A,'Weekly Log'!$C:$C,A22,'Weekly Log'!$E:$E,"Yes"))) | O22: =IF(N22="","",MAX(0,INT((TODAY()-N22)/7))) | Q22: =IF(A22="","",IFERROR(LOOKUP(2,1/(('Weekly Log'!$C$4:$C$1003=A22)*('Weekly Log'!$I$4:$I$1003<>"")),'Weekly Log'!$I$4:$I$1003),""))
J23: =IF(A23="","",COUNTIF('Weekly Log'!$C:$C,A23)) | K23: =IF(A23="","",COUNTIFS('Weekly Log'!$C:$C,A23,'Weekly Log'!$E:$E,"Yes")) | L23: =IF(A23="","",IF(J23=0,"",K23/J23)) | M23: =IF(A23="","",IFERROR((SUMIFS('Weekly Log'!$F:$F,'Weekly Log'!$C:$C,A23)+SUMIFS('Weekly Log'!$G:$G,'Weekly Log'!$C:$C,A23))/(COUNTIFS('Weekly Log'!$C:$C,A23,'Weekly Log'!$F:$F,"<>")+COUNTIFS('Weekly Log'!$C:$C,A23,'Weekly Log'!$G:$G,"<>")),"")) | N23: =IF(A23="","",IF(K23=0,"",_xlfn.MAXIFS('Weekly Log'!$A:$A,'Weekly Log'!$C:$C,A23,'Weekly Log'!$E:$E,"Yes"))) | O23: =IF(N23="","",MAX(0,INT((TODAY()-N23)/7))) | Q23: =IF(A23="","",IFERROR(LOOKUP(2,1/(('Weekly Log'!$C$4:$C$1003=A23)*('Weekly Log'!$I$4:$I$1003<>"")),'Weekly Log'!$I$4:$I$1003),""))
... J503: =IF(A503="","",COUNTIF('Weekly Log'!$C:$C,A503)) | K503: =IF(A503="","",COUNTIFS('Weekly Log'!$C:$C,A503,'Weekly Log'!$E:$E,"Yes")) | L503: =IF(A503="","",IF(J503=0,"",K503/J503)) | M503: =IF(A503="","",IFERROR((SUMIFS('Weekly Log'!$F:$F,'Weekly Log'!$C:$C,A503)+SUMIFS('Weekly Log'!$G:$G,'Weekly Log'!$C:$C,A503))/(COUNTIFS('Weekly Log'!$C:$C,A503,'Weekly Log'!$F:$F,"<>")+COUNTIFS('Weekly Log'!$C:$C,A503,'Weekly Log'!$G:$G,"<>")),"")) | N503: =IF(A503="","",IF(K503=0,"",_xlfn.MAXIFS('Weekly Log'!$A:$A,'Weekly Log'!$C:$C,A503,'Weekly Log'!$E:$E,"Yes"))) | O503: =IF(N503="","",MAX(0,INT((TODAY()-N503)/7))) | Q503: =IF(A503="","",IFERROR(LOOKUP(2,1/(('Weekly Log'!$C$4:$C$1003=A503)*('Weekly Log'!$I$4:$I$1003<>"")),'Weekly Log'!$I$4:$I$1003),""))

Sheet Weekly Log
A1: Weekly Log — one row per option offered, every week
A2: Sunday: add every option in the pitch (picked = No). After you choose: flip picks to Yes. Next week's debrief: fill ratings 1–5, verdict, and what to change in tweak.
A3: week_of | B3: slot | C3: recipe_id | D3: recipe_name | E3: picked | F3: rating_lily | G3: rating_andrei | H3: verdict | I3: tweak | J3: notes | K3: source | L3: grocery_rank
A4: 46306 | B4: Lunch 1 | C4: EX03 | D4: =IF(C4="","",IFERROR(INDEX(Recipes!$B:$B,MATCH(C4,Recipes!$A:$A,0)),"⚠ unknown recipe_id")) -> Ciorbă de perișoare (meatball soup) | E4: Yes | F4: 4 | G4: 5 | H4: Tweak | I4: Extra lovage, more borș | J4: Even better on day 3 | K4: =IF(C4="","",IFERROR(INDEX(Recipes!$C:$C,MATCH(C4,Recipes!$A:$A,0)),"")) -> Own | L4: =IF(AND(A4='Grocery List'!$B$3,E4="Yes"),COUNTIFS($A$4:A4,'Grocery List'!$B$3,$E$4:E4,"Yes"),"")
A5: 46306 | B5: Dinner 1 | C5: EX07 | D5: =IF(C5="","",IFERROR(INDEX(Recipes!$B:$B,MATCH(C5,Recipes!$A:$A,0)),"⚠ unknown recipe_id")) -> Tomato egg stir-fry | E5: Yes | F5: 5 | G5: 4 | H5: Again | J5: Andrei wants it weekly | K5: =IF(C5="","",IFERROR(INDEX(Recipes!$C:$C,MATCH(C5,Recipes!$A:$A,0)),"")) -> Own | L5: =IF(AND(A5='Grocery List'!$B$3,E5="Yes"),COUNTIFS($A$4:A5,'Grocery List'!$B$3,$E$4:E5,"Yes"),"")
A6: 46313 | B6: Lunch 1 | C6: EX01 | D6: =IF(C6="","",IFERROR(INDEX(Recipes!$B:$B,MATCH(C6,Recipes!$A:$A,0)),"⚠ unknown recipe_id")) -> Chicken burrito bowls | E6: No | K6: =IF(C6="","",IFERROR(INDEX(Recipes!$C:$C,MATCH(C6,Recipes!$A:$A,0)),"")) -> AI | L6: =IF(AND(A6='Grocery List'!$B$3,E6="Yes"),COUNTIFS($A$4:A6,'Grocery List'!$B$3,$E$4:E6,"Yes"),"")
A7: 46313 | B7: Lunch 1 | C7: EX02 | D7: =IF(C7="","",IFERROR(INDEX(Recipes!$B:$B,MATCH(C7,Recipes!$A:$A,0)),"⚠ unknown recipe_id")) -> Cold sesame noodles with cucumber | E7: Yes | K7: =IF(C7="","",IFERROR(INDEX(Recipes!$C:$C,MATCH(C7,Recipes!$A:$A,0)),"")) -> AI | L7: =IF(AND(A7='Grocery List'!$B$3,E7="Yes"),COUNTIFS($A$4:A7,'Grocery List'!$B$3,$E$4:E7,"Yes"),"") -> 1
A8: 46313 | B8: Lunch 2 | C8: EX03 | D8: =IF(C8="","",IFERROR(INDEX(Recipes!$B:$B,MATCH(C8,Recipes!$A:$A,0)),"⚠ unknown recipe_id")) -> Ciorbă de perișoare (meatball soup) | E8: Yes | K8: =IF(C8="","",IFERROR(INDEX(Recipes!$C:$C,MATCH(C8,Recipes!$A:$A,0)),"")) -> Own | L8: =IF(AND(A8='Grocery List'!$B$3,E8="Yes"),COUNTIFS($A$4:A8,'Grocery List'!$B$3,$E$4:E8,"Yes"),"") -> 2
A9: 46313 | B9: Lunch 2 | C9: EX04 | D9: =IF(C9="","",IFERROR(INDEX(Recipes!$B:$B,MATCH(C9,Recipes!$A:$A,0)),"⚠ unknown recipe_id")) -> Greek chicken orzo | E9: No | K9: =IF(C9="","",IFERROR(INDEX(Recipes!$C:$C,MATCH(C9,Recipes!$A:$A,0)),"")) -> AI | L9: =IF(AND(A9='Grocery List'!$B$3,E9="Yes"),COUNTIFS($A$4:A9,'Grocery List'!$B$3,$E$4:E9,"Yes"),"")
A10: 46313 | B10: Dinner 1 | C10: EX05 | D10: =IF(C10="","",IFERROR(INDEX(Recipes!$B:$B,MATCH(C10,Recipes!$A:$A,0)),"⚠ unknown recipe_id")) -> Sheet-pan sausage, peppers & potatoes | E10: Yes | K10: =IF(C10="","",IFERROR(INDEX(Recipes!$C:$C,MATCH(C10,Recipes!$A:$A,0)),"")) -> AI | L10: =IF(AND(A10='Grocery List'!$B$3,E10="Yes"),COUNTIFS($A$4:A10,'Grocery List'!$B$3,$E$4:E10,"Yes"),"") -> 3
A11: 46313 | B11: Dinner 1 | C11: EX06 | D11: =IF(C11="","",IFERROR(INDEX(Recipes!$B:$B,MATCH(C11,Recipes!$A:$A,0)),"⚠ unknown recipe_id")) -> Red-braised pork belly (hong shao rou) | E11: No | K11: =IF(C11="","",IFERROR(INDEX(Recipes!$C:$C,MATCH(C11,Recipes!$A:$A,0)),"")) -> AI | L11: =IF(AND(A11='Grocery List'!$B$3,E11="Yes"),COUNTIFS($A$4:A11,'Grocery List'!$B$3,$E$4:E11,"Yes"),"")
A12: 46313 | B12: Dinner 2 | C12: EX07 | D12: =IF(C12="","",IFERROR(INDEX(Recipes!$B:$B,MATCH(C12,Recipes!$A:$A,0)),"⚠ unknown recipe_id")) -> Tomato egg stir-fry | E12: No | K12: =IF(C12="","",IFERROR(INDEX(Recipes!$C:$C,MATCH(C12,Recipes!$A:$A,0)),"")) -> Own | L12: =IF(AND(A12='Grocery List'!$B$3,E12="Yes"),COUNTIFS($A$4:A12,'Grocery List'!$B$3,$E$4:E12,"Yes"),"")
A13: 46313 | B13: Dinner 2 | C13: EX08 | D13: =IF(C13="","",IFERROR(INDEX(Recipes!$B:$B,MATCH(C13,Recipes!$A:$A,0)),"⚠ unknown recipe_id")) -> Chicken papricaș with mămăligă | E13: Yes | K13: =IF(C13="","",IFERROR(INDEX(Recipes!$C:$C,MATCH(C13,Recipes!$A:$A,0)),"")) -> AI | L13: =IF(AND(A13='Grocery List'!$B$3,E13="Yes"),COUNTIFS($A$4:A13,'Grocery List'!$B$3,$E$4:E13,"Yes"),"") -> 4
D14: =IF(C14="","",IFERROR(INDEX(Recipes!$B:$B,MATCH(C14,Recipes!$A:$A,0)),"⚠ unknown recipe_id")) | K14: =IF(C14="","",IFERROR(INDEX(Recipes!$C:$C,MATCH(C14,Recipes!$A:$A,0)),"")) | L14: =IF(AND(A14='Grocery List'!$B$3,E14="Yes"),COUNTIFS($A$4:A14,'Grocery List'!$B$3,$E$4:E14,"Yes"),"")
D15: =IF(C15="","",IFERROR(INDEX(Recipes!$B:$B,MATCH(C15,Recipes!$A:$A,0)),"⚠ unknown recipe_id")) | K15: =IF(C15="","",IFERROR(INDEX(Recipes!$C:$C,MATCH(C15,Recipes!$A:$A,0)),"")) | L15: =IF(AND(A15='Grocery List'!$B$3,E15="Yes"),COUNTIFS($A$4:A15,'Grocery List'!$B$3,$E$4:E15,"Yes"),"")
D16: =IF(C16="","",IFERROR(INDEX(Recipes!$B:$B,MATCH(C16,Recipes!$A:$A,0)),"⚠ unknown recipe_id")) | K16: =IF(C16="","",IFERROR(INDEX(Recipes!$C:$C,MATCH(C16,Recipes!$A:$A,0)),"")) | L16: =IF(AND(A16='Grocery List'!$B$3,E16="Yes"),COUNTIFS($A$4:A16,'Grocery List'!$B$3,$E$4:E16,"Yes"),"")
D17: =IF(C17="","",IFERROR(INDEX(Recipes!$B:$B,MATCH(C17,Recipes!$A:$A,0)),"⚠ unknown recipe_id")) | K17: =IF(C17="","",IFERROR(INDEX(Recipes!$C:$C,MATCH(C17,Recipes!$A:$A,0)),"")) | L17: =IF(AND(A17='Grocery List'!$B$3,E17="Yes"),COUNTIFS($A$4:A17,'Grocery List'!$B$3,$E$4:E17,"Yes"),"")
D18: =IF(C18="","",IFERROR(INDEX(Recipes!$B:$B,MATCH(C18,Recipes!$A:$A,0)),"⚠ unknown recipe_id")) | K18: =IF(C18="","",IFERROR(INDEX(Recipes!$C:$C,MATCH(C18,Recipes!$A:$A,0)),"")) | L18: =IF(AND(A18='Grocery List'!$B$3,E18="Yes"),COUNTIFS($A$4:A18,'Grocery List'!$B$3,$E$4:E18,"Yes"),"")
D19: =IF(C19="","",IFERROR(INDEX(Recipes!$B:$B,MATCH(C19,Recipes!$A:$A,0)),"⚠ unknown recipe_id")) | K19: =IF(C19="","",IFERROR(INDEX(Recipes!$C:$C,MATCH(C19,Recipes!$A:$A,0)),"")) | L19: =IF(AND(A19='Grocery List'!$B$3,E19="Yes"),COUNTIFS($A$4:A19,'Grocery List'!$B$3,$E$4:E19,"Yes"),"")
D20: =IF(C20="","",IFERROR(INDEX(Recipes!$B:$B,MATCH(C20,Recipes!$A:$A,0)),"⚠ unknown recipe_id")) | K20: =IF(C20="","",IFERROR(INDEX(Recipes!$C:$C,MATCH(C20,Recipes!$A:$A,0)),"")) | L20: =IF(AND(A20='Grocery List'!$B$3,E20="Yes"),COUNTIFS($A$4:A20,'Grocery List'!$B$3,$E$4:E20,"Yes"),"")
D21: =IF(C21="","",IFERROR(INDEX(Recipes!$B:$B,MATCH(C21,Recipes!$A:$A,0)),"⚠ unknown recipe_id")) | K21: =IF(C21="","",IFERROR(INDEX(Recipes!$C:$C,MATCH(C21,Recipes!$A:$A,0)),"")) | L21: =IF(AND(A21='Grocery List'!$B$3,E21="Yes"),COUNTIFS($A$4:A21,'Grocery List'!$B$3,$E$4:E21,"Yes"),"")
D22: =IF(C22="","",IFERROR(INDEX(Recipes!$B:$B,MATCH(C22,Recipes!$A:$A,0)),"⚠ unknown recipe_id")) | K22: =IF(C22="","",IFERROR(INDEX(Recipes!$C:$C,MATCH(C22,Recipes!$A:$A,0)),"")) | L22: =IF(AND(A22='Grocery List'!$B$3,E22="Yes"),COUNTIFS($A$4:A22,'Grocery List'!$B$3,$E$4:E22,"Yes"),"")
D23: =IF(C23="","",IFERROR(INDEX(Recipes!$B:$B,MATCH(C23,Recipes!$A:$A,0)),"⚠ unknown recipe_id")) | K23: =IF(C23="","",IFERROR(INDEX(Recipes!$C:$C,MATCH(C23,Recipes!$A:$A,0)),"")) | L23: =IF(AND(A23='Grocery List'!$B$3,E23="Yes"),COUNTIFS($A$4:A23,'Grocery List'!$B$3,$E$4:E23,"Yes"),"")
D24: =IF(C24="","",IFERROR(INDEX(Recipes!$B:$B,MATCH(C24,Recipes!$A:$A,0)),"⚠ unknown recipe_id")) | K24: =IF(C24="","",IFERROR(INDEX(Recipes!$C:$C,MATCH(C24,Recipes!$A:$A,0)),"")) | L24: =IF(AND(A24='Grocery List'!$B$3,E24="Yes"),COUNTIFS($A$4:A24,'Grocery List'!$B$3,$E$4:E24,"Yes"),"")
D25: =IF(C25="","",IFERROR(INDEX(Recipes!$B:$B,MATCH(C25,Recipes!$A:$A,0)),"⚠ unknown recipe_id")) | K25: =IF(C25="","",IFERROR(INDEX(Recipes!$C:$C,MATCH(C25,Recipes!$A:$A,0)),"")) | L25: =IF(AND(A25='Grocery List'!$B$3,E25="Yes"),COUNTIFS($A$4:A25,'Grocery List'!$B$3,$E$4:E25,"Yes"),"")
... D1003: =IF(C1003="","",IFERROR(INDEX(Recipes!$B:$B,MATCH(C1003,Recipes!$A:$A,0)),"⚠ unknown recipe_id")) | K1003: =IF(C1003="","",IFERROR(INDEX(Recipes!$C:$C,MATCH(C1003,Recipes!$A:$A,0)),"")) | L1003: =IF(AND(A1003='Grocery List'!$B$3,E1003="Yes"),COUNTIFS($A$4:A1003,'Grocery List'!$B$3,$E$4:E1003,"Yes"),"")

Sheet Ingredients
A1: Ingredients — one row per ingredient in each recipe
A2: Pick the ingredient from the dropdown (add it to the Ingredient Catalog first if it's new). Quantity is per batch, in the catalog's unit. Leave quantity blank for 'to taste'.
A3: recipe_id | B3: recipe_name | C3: ingredient | D3: quantity | E3: unit | F3: prep_note | G3: times_needed_this_week | H3: qty_this_week
A4: EX02 | B4: =IF(A4="","",IFERROR(INDEX(Recipes!$B:$B,MATCH(A4,Recipes!$A:$A,0)),"⚠ unknown recipe_id")) -> Cold sesame noodles with cucumber | C4: Wheat noodles | D4: 1 | E4: =IF(C4="","",IFERROR(INDEX('Ingredient Catalog'!$C:$C,MATCH(C4,'Ingredient Catalog'!$A:$A,0)),"⚠ not in catalog")) -> lb | G4: =IF(A4="","",COUNTIFS('Weekly Log'!$A:$A,'Grocery List'!$B$3,'Weekly Log'!$C:$C,A4,'Weekly Log'!$E:$E,"Yes")) -> 1 | H4: =IF(OR(A4="",D4=""),"",D4*G4) -> 1
A5: EX02 | B5: =IF(A5="","",IFERROR(INDEX(Recipes!$B:$B,MATCH(A5,Recipes!$A:$A,0)),"⚠ unknown recipe_id")) -> Cold sesame noodles with cucumber | C5: Cucumber | D5: 2 | E5: =IF(C5="","",IFERROR(INDEX('Ingredient Catalog'!$C:$C,MATCH(C5,'Ingredient Catalog'!$A:$A,0)),"⚠ not in catalog")) -> each | F5: smashed | G5: =IF(A5="","",COUNTIFS('Weekly Log'!$A:$A,'Grocery List'!$B$3,'Weekly Log'!$C:$C,A5,'Weekly Log'!$E:$E,"Yes")) -> 1 | H5: =IF(OR(A5="",D5=""),"",D5*G5) -> 2
A6: EX02 | B6: =IF(A6="","",IFERROR(INDEX(Recipes!$B:$B,MATCH(A6,Recipes!$A:$A,0)),"⚠ unknown recipe_id")) -> Cold sesame noodles with cucumber | C6: Chinese sesame paste | D6: 3 | E6: =IF(C6="","",IFERROR(INDEX('Ingredient Catalog'!$C:$C,MATCH(C6,'Ingredient Catalog'!$A:$A,0)),"⚠ not in catalog")) -> tbsp | G6: =IF(A6="","",COUNTIFS('Weekly Log'!$A:$A,'Grocery List'!$B$3,'Weekly Log'!$C:$C,A6,'Weekly Log'!$E:$E,"Yes")) -> 1 | H6: =IF(OR(A6="",D6=""),"",D6*G6) -> 3
A7: EX02 | B7: =IF(A7="","",IFERROR(INDEX(Recipes!$B:$B,MATCH(A7,Recipes!$A:$A,0)),"⚠ unknown recipe_id")) -> Cold sesame noodles with cucumber | C7: Soy sauce | D7: 3 | E7: =IF(C7="","",IFERROR(INDEX('Ingredient Catalog'!$C:$C,MATCH(C7,'Ingredient Catalog'!$A:$A,0)),"⚠ not in catalog")) -> tbsp | G7: =IF(A7="","",COUNTIFS('Weekly Log'!$A:$A,'Grocery List'!$B$3,'Weekly Log'!$C:$C,A7,'Weekly Log'!$E:$E,"Yes")) -> 1 | H7: =IF(OR(A7="",D7=""),"",D7*G7) -> 3
A8: EX02 | B8: =IF(A8="","",IFERROR(INDEX(Recipes!$B:$B,MATCH(A8,Recipes!$A:$A,0)),"⚠ unknown recipe_id")) -> Cold sesame noodles with cucumber | C8: Chinkiang black vinegar | D8: 1 | E8: =IF(C8="","",IFERROR(INDEX('Ingredient Catalog'!$C:$C,MATCH(C8,'Ingredient Catalog'!$A:$A,0)),"⚠ not in catalog")) -> tbsp | G8: =IF(A8="","",COUNTIFS('Weekly Log'!$A:$A,'Grocery List'!$B$3,'Weekly Log'!$C:$C,A8,'Weekly Log'!$E:$E,"Yes")) -> 1 | H8: =IF(OR(A8="",D8=""),"",D8*G8) -> 1
A9: EX02 | B9: =IF(A9="","",IFERROR(INDEX(Recipes!$B:$B,MATCH(A9,Recipes!$A:$A,0)),"⚠ unknown recipe_id")) -> Cold sesame noodles with cucumber | C9: Chili oil | D9: 1 | E9: =IF(C9="","",IFERROR(INDEX('Ingredient Catalog'!$C:$C,MATCH(C9,'Ingredient Catalog'!$A:$A,0)),"⚠ not in catalog")) -> tbsp | G9: =IF(A9="","",COUNTIFS('Weekly Log'!$A:$A,'Grocery List'!$B$3,'Weekly Log'!$C:$C,A9,'Weekly Log'!$E:$E,"Yes")) -> 1 | H9: =IF(OR(A9="",D9=""),"",D9*G9) -> 1
A10: EX02 | B10: =IF(A10="","",IFERROR(INDEX(Recipes!$B:$B,MATCH(A10,Recipes!$A:$A,0)),"⚠ unknown recipe_id")) -> Cold sesame noodles with cucumber | C10: Garlic | D10: 3 | E10: =IF(C10="","",IFERROR(INDEX('Ingredient Catalog'!$C:$C,MATCH(C10,'Ingredient Catalog'!$A:$A,0)),"⚠ not in catalog")) -> clove | F10: grated | G10: =IF(A10="","",COUNTIFS('Weekly Log'!$A:$A,'Grocery List'!$B$3,'Weekly Log'!$C:$C,A10,'Weekly Log'!$E:$E,"Yes")) -> 1 | H10: =IF(OR(A10="",D10=""),"",D10*G10) -> 3
A11: EX02 | B11: =IF(A11="","",IFERROR(INDEX(Recipes!$B:$B,MATCH(A11,Recipes!$A:$A,0)),"⚠ unknown recipe_id")) -> Cold sesame noodles with cucumber | C11: Scallions | D11: 1 | E11: =IF(C11="","",IFERROR(INDEX('Ingredient Catalog'!$C:$C,MATCH(C11,'Ingredient Catalog'!$A:$A,0)),"⚠ not in catalog")) -> bunch | G11: =IF(A11="","",COUNTIFS('Weekly Log'!$A:$A,'Grocery List'!$B$3,'Weekly Log'!$C:$C,A11,'Weekly Log'!$E:$E,"Yes")) -> 1 | H11: =IF(OR(A11="",D11=""),"",D11*G11) -> 1
A12: EX03 | B12: =IF(A12="","",IFERROR(INDEX(Recipes!$B:$B,MATCH(A12,Recipes!$A:$A,0)),"⚠ unknown recipe_id")) -> Ciorbă de perișoare (meatball soup) | C12: Ground pork | D12: 1 | E12: =IF(C12="","",IFERROR(INDEX('Ingredient Catalog'!$C:$C,MATCH(C12,'Ingredient Catalog'!$A:$A,0)),"⚠ not in catalog")) -> lb | G12: =IF(A12="","",COUNTIFS('Weekly Log'!$A:$A,'Grocery List'!$B$3,'Weekly Log'!$C:$C,A12,'Weekly Log'!$E:$E,"Yes")) -> 1 | H12: =IF(OR(A12="",D12=""),"",D12*G12) -> 1
A13: EX03 | B13: =IF(A13="","",IFERROR(INDEX(Recipes!$B:$B,MATCH(A13,Recipes!$A:$A,0)),"⚠ unknown recipe_id")) -> Ciorbă de perișoare (meatball soup) | C13: Rice | D13: 0.33 | E13: =IF(C13="","",IFERROR(INDEX('Ingredient Catalog'!$C:$C,MATCH(C13,'Ingredient Catalog'!$A:$A,0)),"⚠ not in catalog")) -> cup | G13: =IF(A13="","",COUNTIFS('Weekly Log'!$A:$A,'Grocery List'!$B$3,'Weekly Log'!$C:$C,A13,'Weekly Log'!$E:$E,"Yes")) -> 1 | H13: =IF(OR(A13="",D13=""),"",D13*G13) -> 0.33
A14: EX03 | B14: =IF(A14="","",IFERROR(INDEX(Recipes!$B:$B,MATCH(A14,Recipes!$A:$A,0)),"⚠ unknown recipe_id")) -> Ciorbă de perișoare (meatball soup) | C14: Onion | D14: 1 | E14: =IF(C14="","",IFERROR(INDEX('Ingredient Catalog'!$C:$C,MATCH(C14,'Ingredient Catalog'!$A:$A,0)),"⚠ not in catalog")) -> each | F14: diced | G14: =IF(A14="","",COUNTIFS('Weekly Log'!$A:$A,'Grocery List'!$B$3,'Weekly Log'!$C:$C,A14,'Weekly Log'!$E:$E,"Yes")) -> 1 | H14: =IF(OR(A14="",D14=""),"",D14*G14) -> 1
A15: EX03 | B15: =IF(A15="","",IFERROR(INDEX(Recipes!$B:$B,MATCH(A15,Recipes!$A:$A,0)),"⚠ unknown recipe_id")) -> Ciorbă de perișoare (meatball soup) | C15: Carrot | D15: 2 | E15: =IF(C15="","",IFERROR(INDEX('Ingredient Catalog'!$C:$C,MATCH(C15,'Ingredient Catalog'!$A:$A,0)),"⚠ not in catalog")) -> each | G15: =IF(A15="","",COUNTIFS('Weekly Log'!$A:$A,'Grocery List'!$B$3,'Weekly Log'!$C:$C,A15,'Weekly Log'!$E:$E,"Yes")) -> 1 | H15: =IF(OR(A15="",D15=""),"",D15*G15) -> 2
A16: EX03 | B16: =IF(A16="","",IFERROR(INDEX(Recipes!$B:$B,MATCH(A16,Recipes!$A:$A,0)),"⚠ unknown recipe_id")) -> Ciorbă de perișoare (meatball soup) | C16: Lovage (leuștean) | D16: 1 | E16: =IF(C16="","",IFERROR(INDEX('Ingredient Catalog'!$C:$C,MATCH(C16,'Ingredient Catalog'!$A:$A,0)),"⚠ not in catalog")) -> bunch | G16: =IF(A16="","",COUNTIFS('Weekly Log'!$A:$A,'Grocery List'!$B$3,'Weekly Log'!$C:$C,A16,'Weekly Log'!$E:$E,"Yes")) -> 1 | H16: =IF(OR(A16="",D16=""),"",D16*G16) -> 1
A17: EX03 | B17: =IF(A17="","",IFERROR(INDEX(Recipes!$B:$B,MATCH(A17,Recipes!$A:$A,0)),"⚠ unknown recipe_id")) -> Ciorbă de perișoare (meatball soup) | C17: Borș | D17: 2 | E17: =IF(C17="","",IFERROR(INDEX('Ingredient Catalog'!$C:$C,MATCH(C17,'Ingredient Catalog'!$A:$A,0)),"⚠ not in catalog")) -> cup | G17: =IF(A17="","",COUNTIFS('Weekly Log'!$A:$A,'Grocery List'!$B$3,'Weekly Log'!$C:$C,A17,'Weekly Log'!$E:$E,"Yes")) -> 1 | H17: =IF(OR(A17="",D17=""),"",D17*G17) -> 2
A18: EX03 | B18: =IF(A18="","",IFERROR(INDEX(Recipes!$B:$B,MATCH(A18,Recipes!$A:$A,0)),"⚠ unknown recipe_id")) -> Ciorbă de perișoare (meatball soup) | C18: Egg | D18: 1 | E18: =IF(C18="","",IFERROR(INDEX('Ingredient Catalog'!$C:$C,MATCH(C18,'Ingredient Catalog'!$A:$A,0)),"⚠ not in catalog")) -> each | G18: =IF(A18="","",COUNTIFS('Weekly Log'!$A:$A,'Grocery List'!$B$3,'Weekly Log'!$C:$C,A18,'Weekly Log'!$E:$E,"Yes")) -> 1 | H18: =IF(OR(A18="",D18=""),"",D18*G18) -> 1
A19: EX03 | B19: =IF(A19="","",IFERROR(INDEX(Recipes!$B:$B,MATCH(A19,Recipes!$A:$A,0)),"⚠ unknown recipe_id")) -> Ciorbă de perișoare (meatball soup) | C19: Sour cream | D19: 1 | E19: =IF(C19="","",IFERROR(INDEX('Ingredient Catalog'!$C:$C,MATCH(C19,'Ingredient Catalog'!$A:$A,0)),"⚠ not in catalog")) -> cup | F19: to serve | G19: =IF(A19="","",COUNTIFS('Weekly Log'!$A:$A,'Grocery List'!$B$3,'Weekly Log'!$C:$C,A19,'Weekly Log'!$E:$E,"Yes")) -> 1 | H19: =IF(OR(A19="",D19=""),"",D19*G19) -> 1
A20: EX03 | B20: =IF(A20="","",IFERROR(INDEX(Recipes!$B:$B,MATCH(A20,Recipes!$A:$A,0)),"⚠ unknown recipe_id")) -> Ciorbă de perișoare (meatball soup) | C20: Tomato paste | D20: 2 | E20: =IF(C20="","",IFERROR(INDEX('Ingredient Catalog'!$C:$C,MATCH(C20,'Ingredient Catalog'!$A:$A,0)),"⚠ not in catalog")) -> tbsp | G20: =IF(A20="","",COUNTIFS('Weekly Log'!$A:$A,'Grocery List'!$B$3,'Weekly Log'!$C:$C,A20,'Weekly Log'!$E:$E,"Yes")) -> 1 | H20: =IF(OR(A20="",D20=""),"",D20*G20) -> 2
A21: EX05 | B21: =IF(A21="","",IFERROR(INDEX(Recipes!$B:$B,MATCH(A21,Recipes!$A:$A,0)),"⚠ unknown recipe_id")) -> Sheet-pan sausage, peppers & potatoes | C21: Italian sausage | D21: 1.5 | E21: =IF(C21="","",IFERROR(INDEX('Ingredient Catalog'!$C:$C,MATCH(C21,'Ingredient Catalog'!$A:$A,0)),"⚠ not in catalog")) -> lb | G21: =IF(A21="","",COUNTIFS('Weekly Log'!$A:$A,'Grocery List'!$B$3,'Weekly Log'!$C:$C,A21,'Weekly Log'!$E:$E,"Yes")) -> 1 | H21: =IF(OR(A21="",D21=""),"",D21*G21) -> 1.5
A22: EX05 | B22: =IF(A22="","",IFERROR(INDEX(Recipes!$B:$B,MATCH(A22,Recipes!$A:$A,0)),"⚠ unknown recipe_id")) -> Sheet-pan sausage, peppers & potatoes | C22: Bell pepper | D22: 3 | E22: =IF(C22="","",IFERROR(INDEX('Ingredient Catalog'!$C:$C,MATCH(C22,'Ingredient Catalog'!$A:$A,0)),"⚠ not in catalog")) -> each | F22: strips | G22: =IF(A22="","",COUNTIFS('Weekly Log'!$A:$A,'Grocery List'!$B$3,'Weekly Log'!$C:$C,A22,'Weekly Log'!$E:$E,"Yes")) -> 1 | H22: =IF(OR(A22="",D22=""),"",D22*G22) -> 3
A23: EX05 | B23: =IF(A23="","",IFERROR(INDEX(Recipes!$B:$B,MATCH(A23,Recipes!$A:$A,0)),"⚠ unknown recipe_id")) -> Sheet-pan sausage, peppers & potatoes | C23: Onion | D23: 1 | E23: =IF(C23="","",IFERROR(INDEX('Ingredient Catalog'!$C:$C,MATCH(C23,'Ingredient Catalog'!$A:$A,0)),"⚠ not in catalog")) -> each | F23: wedges | G23: =IF(A23="","",COUNTIFS('Weekly Log'!$A:$A,'Grocery List'!$B$3,'Weekly Log'!$C:$C,A23,'Weekly Log'!$E:$E,"Yes")) -> 1 | H23: =IF(OR(A23="",D23=""),"",D23*G23) -> 1
A24: EX05 | B24: =IF(A24="","",IFERROR(INDEX(Recipes!$B:$B,MATCH(A24,Recipes!$A:$A,0)),"⚠ unknown recipe_id")) -> Sheet-pan sausage, peppers & potatoes | C24: Baby potatoes | D24: 1.5 | E24: =IF(C24="","",IFERROR(INDEX('Ingredient Catalog'!$C:$C,MATCH(C24,'Ingredient Catalog'!$A:$A,0)),"⚠ not in catalog")) -> lb | F24: halved | G24: =IF(A24="","",COUNTIFS('Weekly Log'!$A:$A,'Grocery List'!$B$3,'Weekly Log'!$C:$C,A24,'Weekly Log'!$E:$E,"Yes")) -> 1 | H24: =IF(OR(A24="",D24=""),"",D24*G24) -> 1.5
A25: EX05 | B25: =IF(A25="","",IFERROR(INDEX(Recipes!$B:$B,MATCH(A25,Recipes!$A:$A,0)),"⚠ unknown recipe_id")) -> Sheet-pan sausage, peppers & potatoes | C25: Olive oil | D25: 3 | E25: =IF(C25="","",IFERROR(INDEX('Ingredient Catalog'!$C:$C,MATCH(C25,'Ingredient Catalog'!$A:$A,0)),"⚠ not in catalog")) -> tbsp | G25: =IF(A25="","",COUNTIFS('Weekly Log'!$A:$A,'Grocery List'!$B$3,'Weekly Log'!$C:$C,A25,'Weekly Log'!$E:$E,"Yes")) -> 1 | H25: =IF(OR(A25="",D25=""),"",D25*G25) -> 3
A26: EX05 | B26: =IF(A26="","",IFERROR(INDEX(Recipes!$B:$B,MATCH(A26,Recipes!$A:$A,0)),"⚠ unknown recipe_id")) -> Sheet-pan sausage, peppers & potatoes | C26: Garlic | D26: 4 | E26: =IF(C26="","",IFERROR(INDEX('Ingredient Catalog'!$C:$C,MATCH(C26,'Ingredient Catalog'!$A:$A,0)),"⚠ not in catalog")) -> clove | G26: =IF(A26="","",COUNTIFS('Weekly Log'!$A:$A,'Grocery List'!$B$3,'Weekly Log'!$C:$C,A26,'Weekly Log'!$E:$E,"Yes")) -> 1 | H26: =IF(OR(A26="",D26=""),"",D26*G26) -> 4
A27: EX08 | B27: =IF(A27="","",IFERROR(INDEX(Recipes!$B:$B,MATCH(A27,Recipes!$A:$A,0)),"⚠ unknown recipe_id")) -> Chicken papricaș with mămăligă | C27: Chicken thighs | D27: 2 | E27: =IF(C27="","",IFERROR(INDEX('Ingredient Catalog'!$C:$C,MATCH(C27,'Ingredient Catalog'!$A:$A,0)),"⚠ not in catalog")) -> lb | G27: =IF(A27="","",COUNTIFS('Weekly Log'!$A:$A,'Grocery List'!$B$3,'Weekly Log'!$C:$C,A27,'Weekly Log'!$E:$E,"Yes")) -> 1 | H27: =IF(OR(A27="",D27=""),"",D27*G27) -> 2
A28: EX08 | B28: =IF(A28="","",IFERROR(INDEX(Recipes!$B:$B,MATCH(A28,Recipes!$A:$A,0)),"⚠ unknown recipe_id")) -> Chicken papricaș with mămăligă | C28: Onion | D28: 2 | E28: =IF(C28="","",IFERROR(INDEX('Ingredient Catalog'!$C:$C,MATCH(C28,'Ingredient Catalog'!$A:$A,0)),"⚠ not in catalog")) -> each | G28: =IF(A28="","",COUNTIFS('Weekly Log'!$A:$A,'Grocery List'!$B$3,'Weekly Log'!$C:$C,A28,'Weekly Log'!$E:$E,"Yes")) -> 1 | H28: =IF(OR(A28="",D28=""),"",D28*G28) -> 2
A29: EX08 | B29: =IF(A29="","",IFERROR(INDEX(Recipes!$B:$B,MATCH(A29,Recipes!$A:$A,0)),"⚠ unknown recipe_id")) -> Chicken papricaș with mămăligă | C29: Sweet paprika | D29: 2 | E29: =IF(C29="","",IFERROR(INDEX('Ingredient Catalog'!$C:$C,MATCH(C29,'Ingredient Catalog'!$A:$A,0)),"⚠ not in catalog")) -> tbsp | G29: =IF(A29="","",COUNTIFS('Weekly Log'!$A:$A,'Grocery List'!$B$3,'Weekly Log'!$C:$C,A29,'Weekly Log'!$E:$E,"Yes")) -> 1 | H29: =IF(OR(A29="",D29=""),"",D29*G29) -> 2
A30: EX08 | B30: =IF(A30="","",IFERROR(INDEX(Recipes!$B:$B,MATCH(A30,Recipes!$A:$A,0)),"⚠ unknown recipe_id")) -> Chicken papricaș with mămăligă | C30: Sour cream | D30: 1 | E30: =IF(C30="","",IFERROR(INDEX('Ingredient Catalog'!$C:$C,MATCH(C30,'Ingredient Catalog'!$A:$A,0)),"⚠ not in catalog")) -> cup | G30: =IF(A30="","",COUNTIFS('Weekly Log'!$A:$A,'Grocery List'!$B$3,'Weekly Log'!$C:$C,A30,'Weekly Log'!$E:$E,"Yes")) -> 1 | H30: =IF(OR(A30="",D30=""),"",D30*G30) -> 1
A31: EX08 | B31: =IF(A31="","",IFERROR(INDEX(Recipes!$B:$B,MATCH(A31,Recipes!$A:$A,0)),"⚠ unknown recipe_id")) -> Chicken papricaș with mămăligă | C31: Bell pepper | D31: 1 | E31: =IF(C31="","",IFERROR(INDEX('Ingredient Catalog'!$C:$C,MATCH(C31,'Ingredient Catalog'!$A:$A,0)),"⚠ not in catalog")) -> each | G31: =IF(A31="","",COUNTIFS('Weekly Log'!$A:$A,'Grocery List'!$B$3,'Weekly Log'!$C:$C,A31,'Weekly Log'!$E:$E,"Yes")) -> 1 | H31: =IF(OR(A31="",D31=""),"",D31*G31) -> 1
A32: EX08 | B32: =IF(A32="","",IFERROR(INDEX(Recipes!$B:$B,MATCH(A32,Recipes!$A:$A,0)),"⚠ unknown recipe_id")) -> Chicken papricaș with mămăligă | C32: Flour | D32: 2 | E32: =IF(C32="","",IFERROR(INDEX('Ingredient Catalog'!$C:$C,MATCH(C32,'Ingredient Catalog'!$A:$A,0)),"⚠ not in catalog")) -> tbsp | G32: =IF(A32="","",COUNTIFS('Weekly Log'!$A:$A,'Grocery List'!$B$3,'Weekly Log'!$C:$C,A32,'Weekly Log'!$E:$E,"Yes")) -> 1 | H32: =IF(OR(A32="",D32=""),"",D32*G32) -> 2
A33: EX08 | B33: =IF(A33="","",IFERROR(INDEX(Recipes!$B:$B,MATCH(A33,Recipes!$A:$A,0)),"⚠ unknown recipe_id")) -> Chicken papricaș with mămăligă | C33: Cornmeal (mălai) | D33: 1.5 | E33: =IF(C33="","",IFERROR(INDEX('Ingredient Catalog'!$C:$C,MATCH(C33,'Ingredient Catalog'!$A:$A,0)),"⚠ not in catalog")) -> cup | G33: =IF(A33="","",COUNTIFS('Weekly Log'!$A:$A,'Grocery List'!$B$3,'Weekly Log'!$C:$C,A33,'Weekly Log'!$E:$E,"Yes")) -> 1 | H33: =IF(OR(A33="",D33=""),"",D33*G33) -> 1.5
A34: EX08 | B34: =IF(A34="","",IFERROR(INDEX(Recipes!$B:$B,MATCH(A34,Recipes!$A:$A,0)),"⚠ unknown recipe_id")) -> Chicken papricaș with mămăligă | C34: Salt | E34: =IF(C34="","",IFERROR(INDEX('Ingredient Catalog'!$C:$C,MATCH(C34,'Ingredient Catalog'!$A:$A,0)),"⚠ not in catalog")) -> to taste | G34: =IF(A34="","",COUNTIFS('Weekly Log'!$A:$A,'Grocery List'!$B$3,'Weekly Log'!$C:$C,A34,'Weekly Log'!$E:$E,"Yes")) -> 1 | H34: =IF(OR(A34="",D34=""),"",D34*G34)
A35: EX07 | B35: =IF(A35="","",IFERROR(INDEX(Recipes!$B:$B,MATCH(A35,Recipes!$A:$A,0)),"⚠ unknown recipe_id")) -> Tomato egg stir-fry | C35: Egg | D35: 4 | E35: =IF(C35="","",IFERROR(INDEX('Ingredient Catalog'!$C:$C,MATCH(C35,'Ingredient Catalog'!$A:$A,0)),"⚠ not in catalog")) -> each | G35: =IF(A35="","",COUNTIFS('Weekly Log'!$A:$A,'Grocery List'!$B$3,'Weekly Log'!$C:$C,A35,'Weekly Log'!$E:$E,"Yes")) -> 0 | H35: =IF(OR(A35="",D35=""),"",D35*G35) -> 0
A36: EX07 | B36: =IF(A36="","",IFERROR(INDEX(Recipes!$B:$B,MATCH(A36,Recipes!$A:$A,0)),"⚠ unknown recipe_id")) -> Tomato egg stir-fry | C36: Scallions | D36: 1 | E36: =IF(C36="","",IFERROR(INDEX('Ingredient Catalog'!$C:$C,MATCH(C36,'Ingredient Catalog'!$A:$A,0)),"⚠ not in catalog")) -> bunch | G36: =IF(A36="","",COUNTIFS('Weekly Log'!$A:$A,'Grocery List'!$B$3,'Weekly Log'!$C:$C,A36,'Weekly Log'!$E:$E,"Yes")) -> 0 | H36: =IF(OR(A36="",D36=""),"",D36*G36) -> 0
B37: =IF(A37="","",IFERROR(INDEX(Recipes!$B:$B,MATCH(A37,Recipes!$A:$A,0)),"⚠ unknown recipe_id")) | E37: =IF(C37="","",IFERROR(INDEX('Ingredient Catalog'!$C:$C,MATCH(C37,'Ingredient Catalog'!$A:$A,0)),"⚠ not in catalog")) | G37: =IF(A37="","",COUNTIFS('Weekly Log'!$A:$A,'Grocery List'!$B$3,'Weekly Log'!$C:$C,A37,'Weekly Log'!$E:$E,"Yes")) | H37: =IF(OR(A37="",D37=""),"",D37*G37)
B38: =IF(A38="","",IFERROR(INDEX(Recipes!$B:$B,MATCH(A38,Recipes!$A:$A,0)),"⚠ unknown recipe_id")) | E38: =IF(C38="","",IFERROR(INDEX('Ingredient Catalog'!$C:$C,MATCH(C38,'Ingredient Catalog'!$A:$A,0)),"⚠ not in catalog")) | G38: =IF(A38="","",COUNTIFS('Weekly Log'!$A:$A,'Grocery List'!$B$3,'Weekly Log'!$C:$C,A38,'Weekly Log'!$E:$E,"Yes")) | H38: =IF(OR(A38="",D38=""),"",D38*G38)
B39: =IF(A39="","",IFERROR(INDEX(Recipes!$B:$B,MATCH(A39,Recipes!$A:$A,0)),"⚠ unknown recipe_id")) | E39: =IF(C39="","",IFERROR(INDEX('Ingredient Catalog'!$C:$C,MATCH(C39,'Ingredient Catalog'!$A:$A,0)),"⚠ not in catalog")) | G39: =IF(A39="","",COUNTIFS('Weekly Log'!$A:$A,'Grocery List'!$B$3,'Weekly Log'!$C:$C,A39,'Weekly Log'!$E:$E,"Yes")) | H39: =IF(OR(A39="",D39=""),"",D39*G39)
B40: =IF(A40="","",IFERROR(INDEX(Recipes!$B:$B,MATCH(A40,Recipes!$A:$A,0)),"⚠ unknown recipe_id")) | E40: =IF(C40="","",IFERROR(INDEX('Ingredient Catalog'!$C:$C,MATCH(C40,'Ingredient Catalog'!$A:$A,0)),"⚠ not in catalog")) | G40: =IF(A40="","",COUNTIFS('Weekly Log'!$A:$A,'Grocery List'!$B$3,'Weekly Log'!$C:$C,A40,'Weekly Log'!$E:$E,"Yes")) | H40: =IF(OR(A40="",D40=""),"",D40*G40)
...

Sheet Grocery List
A1: Grocery List
A3: Week of | B3: =MAX('Weekly Log'!$A:$A) -> 46313 | C3: ← defaults to the latest week in the log; type a date here to see an older week
A5: This week's picks
A6: Slot | B6: Recipe
A7: =IFERROR(INDEX('Weekly Log'!$B:$B,MATCH(1,'Weekly Log'!$L:$L,0)),"") -> Lunch 1 | B7: =IFERROR(INDEX('Weekly Log'!$D:$D,MATCH(1,'Weekly Log'!$L:$L,0)),"") -> Cold sesame noodles with cucumber
A8: =IFERROR(INDEX('Weekly Log'!$B:$B,MATCH(2,'Weekly Log'!$L:$L,0)),"") -> Lunch 2 | B8: =IFERROR(INDEX('Weekly Log'!$D:$D,MATCH(2,'Weekly Log'!$L:$L,0)),"") -> Ciorbă de perișoare (meatball soup)
A9: =IFERROR(INDEX('Weekly Log'!$B:$B,MATCH(3,'Weekly Log'!$L:$L,0)),"") -> Dinner 1 | B9: =IFERROR(INDEX('Weekly Log'!$D:$D,MATCH(3,'Weekly Log'!$L:$L,0)),"") -> Sheet-pan sausage, peppers & potatoes
A10: =IFERROR(INDEX('Weekly Log'!$B:$B,MATCH(4,'Weekly Log'!$L:$L,0)),"") -> Dinner 2 | B10: =IFERROR(INDEX('Weekly Log'!$D:$D,MATCH(4,'Weekly Log'!$L:$L,0)),"") -> Chicken papricaș with mămăligă
A11: =IFERROR(INDEX('Weekly Log'!$B:$B,MATCH(5,'Weekly Log'!$L:$L,0)),"") | B11: =IFERROR(INDEX('Weekly Log'!$D:$D,MATCH(5,'Weekly Log'!$L:$L,0)),"")
A12: =IFERROR(INDEX('Weekly Log'!$B:$B,MATCH(6,'Weekly Log'!$L:$L,0)),"") | B12: =IFERROR(INDEX('Weekly Log'!$D:$D,MATCH(6,'Weekly Log'!$L:$L,0)),"")
A13: =IFERROR(INDEX('Weekly Log'!$B:$B,MATCH(7,'Weekly Log'!$L:$L,0)),"") | B13: =IFERROR(INDEX('Weekly Log'!$D:$D,MATCH(7,'Weekly Log'!$L:$L,0)),"")
A14: =IFERROR(INDEX('Weekly Log'!$B:$B,MATCH(8,'Weekly Log'!$L:$L,0)),"") | B14: =IFERROR(INDEX('Weekly Log'!$D:$D,MATCH(8,'Weekly Log'!$L:$L,0)),"")
A16: Shopping list (by aisle, pantry staples last — cross off what you already have)
A17: ✓ | B17: Ingredient | C17: Qty | D17: Unit | E17: Aisle | F17: Pantry? | G17: Where / notes
B18: =IFERROR(INDEX('Ingredient Catalog'!$A:$A,MATCH(1,'Ingredient Catalog'!$J:$J,0)),"") -> Cucumber | C18: =IFERROR(IF(INDEX('Ingredient Catalog'!$H:$H,MATCH(1,'Ingredient Catalog'!$J:$J,0))=0,"",INDEX('Ingredient Catalog'!$H:$H,MATCH(1,'Ingredient Catalog'!$J:$J,0))),"") -> 2 | D18: =IFERROR(INDEX('Ingredient Catalog'!$C:$C,MATCH(1,'Ingredient Catalog'!$J:$J,0)),"") -> each | E18: =IFERROR(INDEX('Ingredient Catalog'!$B:$B,MATCH(1,'Ingredient Catalog'!$J:$J,0)),"") -> Produce | F18: =IFERROR(IF(INDEX('Ingredient Catalog'!$D:$D,MATCH(1,'Ingredient Catalog'!$J:$J,0))="Yes","Check pantry",""),"") | G18: =IFERROR(IF(INDEX('Ingredient Catalog'!$E:$E,MATCH(1,'Ingredient Catalog'!$J:$J,0))=0,"",INDEX('Ingredient Catalog'!$E:$E,MATCH(1,'Ingredient Catalog'!$J:$J,0))),"")
B19: =IFERROR(INDEX('Ingredient Catalog'!$A:$A,MATCH(2,'Ingredient Catalog'!$J:$J,0)),"") -> Garlic | C19: =IFERROR(IF(INDEX('Ingredient Catalog'!$H:$H,MATCH(2,'Ingredient Catalog'!$J:$J,0))=0,"",INDEX('Ingredient Catalog'!$H:$H,MATCH(2,'Ingredient Catalog'!$J:$J,0))),"") -> 7 | D19: =IFERROR(INDEX('Ingredient Catalog'!$C:$C,MATCH(2,'Ingredient Catalog'!$J:$J,0)),"") -> clove | E19: =IFERROR(INDEX('Ingredient Catalog'!$B:$B,MATCH(2,'Ingredient Catalog'!$J:$J,0)),"") -> Produce | F19: =IFERROR(IF(INDEX('Ingredient Catalog'!$D:$D,MATCH(2,'Ingredient Catalog'!$J:$J,0))="Yes","Check pantry",""),"") | G19: =IFERROR(IF(INDEX('Ingredient Catalog'!$E:$E,MATCH(2,'Ingredient Catalog'!$J:$J,0))=0,"",INDEX('Ingredient Catalog'!$E:$E,MATCH(2,'Ingredient Catalog'!$J:$J,0))),"")
B20: =IFERROR(INDEX('Ingredient Catalog'!$A:$A,MATCH(3,'Ingredient Catalog'!$J:$J,0)),"") -> Scallions | C20: =IFERROR(IF(INDEX('Ingredient Catalog'!$H:$H,MATCH(3,'Ingredient Catalog'!$J:$J,0))=0,"",INDEX('Ingredient Catalog'!$H:$H,MATCH(3,'Ingredient Catalog'!$J:$J,0))),"") -> 1 | D20: =IFERROR(INDEX('Ingredient Catalog'!$C:$C,MATCH(3,'Ingredient Catalog'!$J:$J,0)),"") -> bunch | E20: =IFERROR(INDEX('Ingredient Catalog'!$B:$B,MATCH(3,'Ingredient Catalog'!$J:$J,0)),"") -> Produce | F20: =IFERROR(IF(INDEX('Ingredient Catalog'!$D:$D,MATCH(3,'Ingredient Catalog'!$J:$J,0))="Yes","Check pantry",""),"") | G20: =IFERROR(IF(INDEX('Ingredient Catalog'!$E:$E,MATCH(3,'Ingredient Catalog'!$J:$J,0))=0,"",INDEX('Ingredient Catalog'!$E:$E,MATCH(3,'Ingredient Catalog'!$J:$J,0))),"")
B21: =IFERROR(INDEX('Ingredient Catalog'!$A:$A,MATCH(4,'Ingredient Catalog'!$J:$J,0)),"") -> Onion | C21: =IFERROR(IF(INDEX('Ingredient Catalog'!$H:$H,MATCH(4,'Ingredient Catalog'!$J:$J,0))=0,"",INDEX('Ingredient Catalog'!$H:$H,MATCH(4,'Ingredient Catalog'!$J:$J,0))),"") -> 4 | D21: =IFERROR(INDEX('Ingredient Catalog'!$C:$C,MATCH(4,'Ingredient Catalog'!$J:$J,0)),"") -> each | E21: =IFERROR(INDEX('Ingredient Catalog'!$B:$B,MATCH(4,'Ingredient Catalog'!$J:$J,0)),"") -> Produce | F21: =IFERROR(IF(INDEX('Ingredient Catalog'!$D:$D,MATCH(4,'Ingredient Catalog'!$J:$J,0))="Yes","Check pantry",""),"") | G21: =IFERROR(IF(INDEX('Ingredient Catalog'!$E:$E,MATCH(4,'Ingredient Catalog'!$J:$J,0))=0,"",INDEX('Ingredient Catalog'!$E:$E,MATCH(4,'Ingredient Catalog'!$J:$J,0))),"")
B22: =IFERROR(INDEX('Ingredient Catalog'!$A:$A,MATCH(5,'Ingredient Catalog'!$J:$J,0)),"") -> Carrot | C22: =IFERROR(IF(INDEX('Ingredient Catalog'!$H:$H,MATCH(5,'Ingredient Catalog'!$J:$J,0))=0,"",INDEX('Ingredient Catalog'!$H:$H,MATCH(5,'Ingredient Catalog'!$J:$J,0))),"") -> 2 | D22: =IFERROR(INDEX('Ingredient Catalog'!$C:$C,MATCH(5,'Ingredient Catalog'!$J:$J,0)),"") -> each | E22: =IFERROR(INDEX('Ingredient Catalog'!$B:$B,MATCH(5,'Ingredient Catalog'!$J:$J,0)),"") -> Produce | F22: =IFERROR(IF(INDEX('Ingredient Catalog'!$D:$D,MATCH(5,'Ingredient Catalog'!$J:$J,0))="Yes","Check pantry",""),"") | G22: =IFERROR(IF(INDEX('Ingredient Catalog'!$E:$E,MATCH(5,'Ingredient Catalog'!$J:$J,0))=0,"",INDEX('Ingredient Catalog'!$E:$E,MATCH(5,'Ingredient Catalog'!$J:$J,0))),"")
B23: =IFERROR(INDEX('Ingredient Catalog'!$A:$A,MATCH(6,'Ingredient Catalog'!$J:$J,0)),"") -> Lovage (leuștean) | C23: =IFERROR(IF(INDEX('Ingredient Catalog'!$H:$H,MATCH(6,'Ingredient Catalog'!$J:$J,0))=0,"",INDEX('Ingredient Catalog'!$H:$H,MATCH(6,'Ingredient Catalog'!$J:$J,0))),"") -> 1 | D23: =IFERROR(INDEX('Ingredient Catalog'!$C:$C,MATCH(6,'Ingredient Catalog'!$J:$J,0)),"") -> bunch | E23: =IFERROR(INDEX('Ingredient Catalog'!$B:$B,MATCH(6,'Ingredient Catalog'!$J:$J,0)),"") -> Produce | F23: =IFERROR(IF(INDEX('Ingredient Catalog'!$D:$D,MATCH(6,'Ingredient Catalog'!$J:$J,0))="Yes","Check pantry",""),"") | G23: =IFERROR(IF(INDEX('Ingredient Catalog'!$E:$E,MATCH(6,'Ingredient Catalog'!$J:$J,0))=0,"",INDEX('Ingredient Catalog'!$E:$E,MATCH(6,'Ingredient Catalog'!$J:$J,0))),"") -> Romanian/Polish deli
B24: =IFERROR(INDEX('Ingredient Catalog'!$A:$A,MATCH(7,'Ingredient Catalog'!$J:$J,0)),"") -> Bell pepper | C24: =IFERROR(IF(INDEX('Ingredient Catalog'!$H:$H,MATCH(7,'Ingredient Catalog'!$J:$J,0))=0,"",INDEX('Ingredient Catalog'!$H:$H,MATCH(7,'Ingredient Catalog'!$J:$J,0))),"") -> 4 | D24: =IFERROR(INDEX('Ingredient Catalog'!$C:$C,MATCH(7,'Ingredient Catalog'!$J:$J,0)),"") -> each | E24: =IFERROR(INDEX('Ingredient Catalog'!$B:$B,MATCH(7,'Ingredient Catalog'!$J:$J,0)),"") -> Produce | F24: =IFERROR(IF(INDEX('Ingredient Catalog'!$D:$D,MATCH(7,'Ingredient Catalog'!$J:$J,0))="Yes","Check pantry",""),"") | G24: =IFERROR(IF(INDEX('Ingredient Catalog'!$E:$E,MATCH(7,'Ingredient Catalog'!$J:$J,0))=0,"",INDEX('Ingredient Catalog'!$E:$E,MATCH(7,'Ingredient Catalog'!$J:$J,0))),"")
B25: =IFERROR(INDEX('Ingredient Catalog'!$A:$A,MATCH(8,'Ingredient Catalog'!$J:$J,0)),"") -> Baby potatoes | C25: =IFERROR(IF(INDEX('Ingredient Catalog'!$H:$H,MATCH(8,'Ingredient Catalog'!$J:$J,0))=0,"",INDEX('Ingredient Catalog'!$H:$H,MATCH(8,'Ingredient Catalog'!$J:$J,0))),"") -> 1.5 | D25: =IFERROR(INDEX('Ingredient Catalog'!$C:$C,MATCH(8,'Ingredient Catalog'!$J:$J,0)),"") -> lb | E25: =IFERROR(INDEX('Ingredient Catalog'!$B:$B,MATCH(8,'Ingredient Catalog'!$J:$J,0)),"") -> Produce | F25: =IFERROR(IF(INDEX('Ingredient Catalog'!$D:$D,MATCH(8,'Ingredient Catalog'!$J:$J,0))="Yes","Check pantry",""),"") | G25: =IFERROR(IF(INDEX('Ingredient Catalog'!$E:$E,MATCH(8,'Ingredient Catalog'!$J:$J,0))=0,"",INDEX('Ingredient Catalog'!$E:$E,MATCH(8,'Ingredient Catalog'!$J:$J,0))),"")
B26: =IFERROR(INDEX('Ingredient Catalog'!$A:$A,MATCH(9,'Ingredient Catalog'!$J:$J,0)),"") -> Ground pork | C26: =IFERROR(IF(INDEX('Ingredient Catalog'!$H:$H,MATCH(9,'Ingredient Catalog'!$J:$J,0))=0,"",INDEX('Ingredient Catalog'!$H:$H,MATCH(9,'Ingredient Catalog'!$J:$J,0))),"") -> 1 | D26: =IFERROR(INDEX('Ingredient Catalog'!$C:$C,MATCH(9,'Ingredient Catalog'!$J:$J,0)),"") -> lb | E26: =IFERROR(INDEX('Ingredient Catalog'!$B:$B,MATCH(9,'Ingredient Catalog'!$J:$J,0)),"") -> Meat & Fish | F26: =IFERROR(IF(INDEX('Ingredient Catalog'!$D:$D,MATCH(9,'Ingredient Catalog'!$J:$J,0))="Yes","Check pantry",""),"") | G26: =IFERROR(IF(INDEX('Ingredient Catalog'!$E:$E,MATCH(9,'Ingredient Catalog'!$J:$J,0))=0,"",INDEX('Ingredient Catalog'!$E:$E,MATCH(9,'Ingredient Catalog'!$J:$J,0))),"")
B27: =IFERROR(INDEX('Ingredient Catalog'!$A:$A,MATCH(10,'Ingredient Catalog'!$J:$J,0)),"") -> Italian sausage | C27: =IFERROR(IF(INDEX('Ingredient Catalog'!$H:$H,MATCH(10,'Ingredient Catalog'!$J:$J,0))=0,"",INDEX('Ingredient Catalog'!$H:$H,MATCH(10,'Ingredient Catalog'!$J:$J,0))),"") -> 1.5 | D27: =IFERROR(INDEX('Ingredient Catalog'!$C:$C,MATCH(10,'Ingredient Catalog'!$J:$J,0)),"") -> lb | E27: =IFERROR(INDEX('Ingredient Catalog'!$B:$B,MATCH(10,'Ingredient Catalog'!$J:$J,0)),"") -> Meat & Fish | F27: =IFERROR(IF(INDEX('Ingredient Catalog'!$D:$D,MATCH(10,'Ingredient Catalog'!$J:$J,0))="Yes","Check pantry",""),"") | G27: =IFERROR(IF(INDEX('Ingredient Catalog'!$E:$E,MATCH(10,'Ingredient Catalog'!$J:$J,0))=0,"",INDEX('Ingredient Catalog'!$E:$E,MATCH(10,'Ingredient Catalog'!$J:$J,0))),"")
B28: =IFERROR(INDEX('Ingredient Catalog'!$A:$A,MATCH(11,'Ingredient Catalog'!$J:$J,0)),"") -> Chicken thighs | C28: =IFERROR(IF(INDEX('Ingredient Catalog'!$H:$H,MATCH(11,'Ingredient Catalog'!$J:$J,0))=0,"",INDEX('Ingredient Catalog'!$H:$H,MATCH(11,'Ingredient Catalog'!$J:$J,0))),"") -> 2 | D28: =IFERROR(INDEX('Ingredient Catalog'!$C:$C,MATCH(11,'Ingredient Catalog'!$J:$J,0)),"") -> lb | E28: =IFERROR(INDEX('Ingredient Catalog'!$B:$B,MATCH(11,'Ingredient Catalog'!$J:$J,0)),"") -> Meat & Fish | F28: =IFERROR(IF(INDEX('Ingredient Catalog'!$D:$D,MATCH(11,'Ingredient Catalog'!$J:$J,0))="Yes","Check pantry",""),"") | G28: =IFERROR(IF(INDEX('Ingredient Catalog'!$E:$E,MATCH(11,'Ingredient Catalog'!$J:$J,0))=0,"",INDEX('Ingredient Catalog'!$E:$E,MATCH(11,'Ingredient Catalog'!$J:$J,0))),"")
B29: =IFERROR(INDEX('Ingredient Catalog'!$A:$A,MATCH(12,'Ingredient Catalog'!$J:$J,0)),"") -> Egg | C29: =IFERROR(IF(INDEX('Ingredient Catalog'!$H:$H,MATCH(12,'Ingredient Catalog'!$J:$J,0))=0,"",INDEX('Ingredient Catalog'!$H:$H,MATCH(12,'Ingredient Catalog'!$J:$J,0))),"") -> 1 | D29: =IFERROR(INDEX('Ingredient Catalog'!$C:$C,MATCH(12,'Ingredient Catalog'!$J:$J,0)),"") -> each | E29: =IFERROR(INDEX('Ingredient Catalog'!$B:$B,MATCH(12,'Ingredient Catalog'!$J:$J,0)),"") -> Dairy & Eggs | F29: =IFERROR(IF(INDEX('Ingredient Catalog'!$D:$D,MATCH(12,'Ingredient Catalog'!$J:$J,0))="Yes","Check pantry",""),"") | G29: =IFERROR(IF(INDEX('Ingredient Catalog'!$E:$E,MATCH(12,'Ingredient Catalog'!$J:$J,0))=0,"",INDEX('Ingredient Catalog'!$E:$E,MATCH(12,'Ingredient Catalog'!$J:$J,0))),"")
B30: =IFERROR(INDEX('Ingredient Catalog'!$A:$A,MATCH(13,'Ingredient Catalog'!$J:$J,0)),"") -> Sour cream | C30: =IFERROR(IF(INDEX('Ingredient Catalog'!$H:$H,MATCH(13,'Ingredient Catalog'!$J:$J,0))=0,"",INDEX('Ingredient Catalog'!$H:$H,MATCH(13,'Ingredient Catalog'!$J:$J,0))),"") -> 2 | D30: =IFERROR(INDEX('Ingredient Catalog'!$C:$C,MATCH(13,'Ingredient Catalog'!$J:$J,0)),"") -> cup | E30: =IFERROR(INDEX('Ingredient Catalog'!$B:$B,MATCH(13,'Ingredient Catalog'!$J:$J,0)),"") -> Dairy & Eggs | F30: =IFERROR(IF(INDEX('Ingredient Catalog'!$D:$D,MATCH(13,'Ingredient Catalog'!$J:$J,0))="Yes","Check pantry",""),"") | G30: =IFERROR(IF(INDEX('Ingredient Catalog'!$E:$E,MATCH(13,'Ingredient Catalog'!$J:$J,0))=0,"",INDEX('Ingredient Catalog'!$E:$E,MATCH(13,'Ingredient Catalog'!$J:$J,0))),"")
B31: =IFERROR(INDEX('Ingredient Catalog'!$A:$A,MATCH(14,'Ingredient Catalog'!$J:$J,0)),"") -> Wheat noodles | C31: =IFERROR(IF(INDEX('Ingredient Catalog'!$H:$H,MATCH(14,'Ingredient Catalog'!$J:$J,0))=0,"",INDEX('Ingredient Catalog'!$H:$H,MATCH(14,'Ingredient Catalog'!$J:$J,0))),"") -> 1 | D31: =IFERROR(INDEX('Ingredient Catalog'!$C:$C,MATCH(14,'Ingredient Catalog'!$J:$J,0)),"") -> lb | E31: =IFERROR(INDEX('Ingredient Catalog'!$B:$B,MATCH(14,'Ingredient Catalog'!$J:$J,0)),"") -> Grains & Noodles | F31: =IFERROR(IF(INDEX('Ingredient Catalog'!$D:$D,MATCH(14,'Ingredient Catalog'!$J:$J,0))="Yes","Check pantry",""),"") | G31: =IFERROR(IF(INDEX('Ingredient Catalog'!$E:$E,MATCH(14,'Ingredient Catalog'!$J:$J,0))=0,"",INDEX('Ingredient Catalog'!$E:$E,MATCH(14,'Ingredient Catalog'!$J:$J,0))),"") -> H Mart
B32: =IFERROR(INDEX('Ingredient Catalog'!$A:$A,MATCH(15,'Ingredient Catalog'!$J:$J,0)),"") -> Borș | C32: =IFERROR(IF(INDEX('Ingredient Catalog'!$H:$H,MATCH(15,'Ingredient Catalog'!$J:$J,0))=0,"",INDEX('Ingredient Catalog'!$H:$H,MATCH(15,'Ingredient Catalog'!$J:$J,0))),"") -> 2 | D32: =IFERROR(INDEX('Ingredient Catalog'!$C:$C,MATCH(15,'Ingredient Catalog'!$J:$J,0)),"") -> cup | E32: =IFERROR(INDEX('Ingredient Catalog'!$B:$B,MATCH(15,'Ingredient Catalog'!$J:$J,0)),"") -> Eastern European | F32: =IFERROR(IF(INDEX('Ingredient Catalog'!$D:$D,MATCH(15,'Ingredient Catalog'!$J:$J,0))="Yes","Check pantry",""),"") | G32: =IFERROR(IF(INDEX('Ingredient Catalog'!$E:$E,MATCH(15,'Ingredient Catalog'!$J:$J,0))=0,"",INDEX('Ingredient Catalog'!$E:$E,MATCH(15,'Ingredient Catalog'!$J:$J,0))),"") -> Romanian/Polish deli
B33: =IFERROR(INDEX('Ingredient Catalog'!$A:$A,MATCH(16,'Ingredient Catalog'!$J:$J,0)),"") -> Rice | C33: =IFERROR(IF(INDEX('Ingredient Catalog'!$H:$H,MATCH(16,'Ingredient Catalog'!$J:$J,0))=0,"",INDEX('Ingredient Catalog'!$H:$H,MATCH(16,'Ingredient Catalog'!$J:$J,0))),"") -> 0.33 | D33: =IFERROR(INDEX('Ingredient Catalog'!$C:$C,MATCH(16,'Ingredient Catalog'!$J:$J,0)),"") -> cup | E33: =IFERROR(INDEX('Ingredient Catalog'!$B:$B,MATCH(16,'Ingredient Catalog'!$J:$J,0)),"") -> Grains & Noodles | F33: =IFERROR(IF(INDEX('Ingredient Catalog'!$D:$D,MATCH(16,'Ingredient Catalog'!$J:$J,0))="Yes","Check pantry",""),"") -> Check pantry | G33: =IFERROR(IF(INDEX('Ingredient Catalog'!$E:$E,MATCH(16,'Ingredient Catalog'!$J:$J,0))=0,"",INDEX('Ingredient Catalog'!$E:$E,MATCH(16,'Ingredient Catalog'!$J:$J,0))),"")
B34: =IFERROR(INDEX('Ingredient Catalog'!$A:$A,MATCH(17,'Ingredient Catalog'!$J:$J,0)),"") -> Cornmeal (mălai) | C34: =IFERROR(IF(INDEX('Ingredient Catalog'!$H:$H,MATCH(17,'Ingredient Catalog'!$J:$J,0))=0,"",INDEX('Ingredient Catalog'!$H:$H,MATCH(17,'Ingredient Catalog'!$J:$J,0))),"") -> 1.5 | D34: =IFERROR(INDEX('Ingredient Catalog'!$C:$C,MATCH(17,'Ingredient Catalog'!$J:$J,0)),"") -> cup | E34: =IFERROR(INDEX('Ingredient Catalog'!$B:$B,MATCH(17,'Ingredient Catalog'!$J:$J,0)),"") -> Grains & Noodles | F34: =IFERROR(IF(INDEX('Ingredient Catalog'!$D:$D,MATCH(17,'Ingredient Catalog'!$J:$J,0))="Yes","Check pantry",""),"") -> Check pantry | G34: =IFERROR(IF(INDEX('Ingredient Catalog'!$E:$E,MATCH(17,'Ingredient Catalog'!$J:$J,0))=0,"",INDEX('Ingredient Catalog'!$E:$E,MATCH(17,'Ingredient Catalog'!$J:$J,0))),"")
